Workbook

Sheet Step 1 - Assessment Plan
B5: Sl. No. | C5: Assessment tool | D5: Marks | E5: Question 1 | F5: Question 2 | G5: Question 3 | H5: Question 4 | I5: Question 5 | J5: Question 6 | L5: TOTAL
B6: 1 | C6: Test I | E6: CO1 | F6: CO1 | G6: CO2 | H6: CO2 | I6: CO2 | J6: CO2
C7: Question wise marks | L7: =SUM(E7:K7) -> 0
E8: Question 1 | F8: Question 2 | G8: Question 3 | H8: Question 4 | I8: Question 5
B9: 2 | C9: Test II | E9: CO3 | F9: CO4 | G9: CO3 | H9: CO1 | I9: CO2
C10: Question wise marks | L10: =SUM(E10:K10) -> 0
E11: Assignment 1 | F11: Assignment 2
B12: 3 | C12: Assignments | E12: CO3 | F12: CO4 | G12: CO5
L13: =SUM(E13:K13) -> 0
C14: Assignment wise marks | L14: =SUM(E14:K14) -> 0
E24: Question 1,2,3 | F24: Question 4,5,6 | G24: Question 3 | H24: Question 4 | I24: Question 5 | J24: Question 6 | K24: Question 7 | L24: Question 8 | M24: Question 9 | N24: Question 10 | O24: Question 11 | P24: Question 12 | Q24: Question 13 | R24: Question 14 | S24: Question 15 | T24: Question 16
C25: End Semester Examination | E25: CO3 | F25: CO4 | G25: CO2 | H25: CO4 | I25: CO4 | J25: CO3 | K25: CO3 | L25: CO1 | M25: CO3 | N25: CO4 | O25: CO1 | P25: CO2 | Q25: CO3 | R25: CO1 | S25: CO4 | T25: CO5
C26: Question wise marks | U26: =SUM(E26:S26) -> 0

Sheet Print Page
A1: Course Code & Title: | B1: ='Front page'!D3 -> 0 | C1: ='Front page'!D2 -> 0
A2: Programme:
A3: Semester: | B3: ='Front page'!D5 -> 0 | C3: ='Front page'!D4 -> 0
A5: CO - PO Mapping
A6: Course Outcomes | B6: PO1 | C6: PO2 | D6: PO3 | E6: PO4 | F6: PO5
A7: CO1: | B7: 3 | C7: 2 | D7: 3 | E7: 2 | F7: 0
A8: CO2: | B8: 3 | C8: 3 | D8: 3 | E8: 2 | F8: 0
A9: CO3: | B9: 3 | C9: 1 | D9: 3 | E9: 2 | F9: 1
A10: CO4: | B10: 3 | C10: 3 | D10: 3 | E10: 2 | F10: 1
A13: CO - Wise Mark Distribution
A14: Course Outcomes | B14: CO1 | C14: CO2 | D14: CO3 | E14: CO4 | F14: CO5
A15: Total Marks` | B15: ='CO Assessment'!BI7 -> 38.75 | C15: ='CO Assessment'!BM7 -> 27.5 | D15: ='CO Assessment'!BQ7 -> 20 | E15: ='CO Assessment'!BU7 -> 13.75 | F15: 0
A17: Definition of CO Attainment Levels
B18: Attainment Level | D18: % of Students Achieving Target
A19: With a linear variation of attainment level from 3 to 2 and 2 to 1 corresponding to the variation in the % of students achieving target from 85 to 50 and 50 to 30 respectively. | B19: 3 | D19: 85
B20: 2 | D20: 50
B21: 1 | D21: 30
A23: CO Attainment
A24: CO Attainment | B24: CO1 | C24: CO2 | D24: CO3 | E24: CO4 | F24: CO5
A25: Corresponding to the Direct assessment | B25: ='CO-PO Direct Attainment'!E12 -> 2.1587302 | C25: ='CO-PO Direct Attainment'!E13 -> 2.6878307 | D25: ='CO-PO Direct Attainment'!E14 -> 2.7936508 | E25: ='CO-PO Direct Attainment'!E15 -> 2.5820106 | F25: ='CO-PO Direct Attainment'!E16
A26: Corresponding to the Indirect assessment | B26: ='CO-PO Indirect Attainment'!L14 -> 2.472 | C26: ='CO-PO Indirect Attainment'!L15 -> 2.424 | D26: ='CO-PO Indirect Attainment'!L16 -> 2.52 | E26: ='CO-PO Indirect Attainment'!L17 -> 2.52
A28: Direct Attainment of PO: | B28: ='Front page'!D2 -> 0
A29: ='Front page'!D3 -> 0 | B29: PO1 | C29: PO2 | D29: PO3 | E29: PO4 | F29: PO5
A30: Direct Attainment | B30: ='CO-PO Direct Attainment'!C33 -> 2.5555556 | C30: ='CO-PO Direct Attainment'!D33 -> 2.5467372 | D30: ='CO-PO Direct Attainment'!E33 -> 2.5555556 | E30: ='CO-PO Direct Attainment'!F33 -> 2.5555556 | F30: ='CO-PO Direct Attainment'!G33 -> 2.6878307
A31: Indirect Attainment | B31: ='CO-PO Indirect Attainment'!D33 -> 2.484 | C31: ='CO-PO Indirect Attainment'!E33 -> 2.4773333 | D31: ='CO-PO Indirect Attainment'!F33 -> 2.484 | E31: ='CO-PO Indirect Attainment'!G33 -> 2.484 | F31: ='CO-PO Indirect Attainment'!H33 -> 2.52
A32: Total Attainment | B32: =(0.8*B30)+(0.2*B31) -> 2.5412444 | C32: =(0.8*C30)+(0.2*C31) -> 2.5328564 | D32: =(0.8*D30)+(0.2*D31) -> 2.5412444 | E32: =(0.8*E30)+(0.2*E31) -> 2.5412444 | F32: =(0.8*F30)+(0.2*F31) -> 2.6542646

Sheet Front page
C2: Course Name : | N2: Colour Coding
C3: Course Code : | N3: Data to be entered
C4: Academic Year: | N4: Data calculated
C5: Semester :
C6: Programme:
C7: Specialization (for M. Tech):
C8: Course Year:
C9: Course Semester :
C10: Credits :
C11: Faculty :
G12: CO-PO MAPPING in terms of grading scores (3,2 and 1)
C13: Course Outcomes | G13: CO-PO Mapping | H13: PO1 | I13: PO2 | J13: PO3 | K13: PO4 | L13: PO5
C14: CO1: | G14: CO1 | H14: 3 | I14: 2 | J14: 3 | K14: 2 | L14: 0
C15: CO2: | G15: CO2 | H15: 3 | I15: 3 | J15: 3 | K15: 2 | L15: 0
C16: CO3: | G16: CO3 | H16: 3 | I16: 1 | J16: 3 | K16: 2 | L16: 1
C17: CO4: | G17: CO4 | H17: 3 | I17: 3 | J17: 3 | K17: 2 | L17: 1
C18: CO5:
C20: Evaluation Policy (in percentage)
C21: Interim Test | D21: 35
C22: End Exam | D22: 50
C23: Continuous Evaluation | D23: 15
C24: Any Other
C25: Total | D25: =SUM(D21:D24) -> 100
C27: Grading Policy
C28: Grade | D28: Lower Limit | E28: Upper Limit
C29: S | D29: 80 | E29: 100
C30: A | D30: 70 | E30: 80
C31: B | D31: 60 | E31: 70
C32: C | D32: 50 | E32: 60
C33: D | D33: 40 | E33: 50
C34: E | D34: 30 | E34: 40
C35: F | D35: 0 | E35: 30

Sheet Step 3-Course - PO Mapping
C8: Course Name : | D8: ='Front page'!D2 -> 0
C9: Course Code : | D9: ='Front page'!D3 -> 0
C10: Semester : | D10: ='Front page'!D9 -> 0
C11: Credits : | D11: ='Front page'!D10 -> 0
C12: Faculty : | D12: ='Front page'!D11 -> 0
D14: PO1 | E14: PO2 | F14: PO3 | G14: PO4 | H14: PO5 | I14: PO6 | J14: PO7 | K14: PO8 | L14: PO9 | M14: PO10 | N14: PO11 | O14: PO12 | P14: PSO1 | Q14: PSO2 | R14: PSO3 | S14: PSO4
B15: CO1
B16: CO2
B17: CO3
B18: CO4
B19: CO5
C21: PO AND CO GRADING SCALE | D21: 3 | E21: Strongly Related (H)
D22: 2 | E22: Moderately Related (M)
D23: 1 | E23: Related (L)
D24: 0 | E24: No relation (Blank Cells)

Sheet CO Assessment
D2: Interim Assessment | X2: End Semester Examination
D4: CO1 | E4: CO1 | F4: CO1 | G4: CO1 | H4: CO1 | I4: CO2 | J4: CO2 | K4: CO2 | L4: CO2 | M4: CO2 | N4: CO2 | O4: CO2 | P4: CO3 | Q4: CO3 | R4: CO3 | S4: CO3 | T4: CO4 | U4: CO4 | X4: CO1 | Y4: CO1 | Z4: CO1 | AA4: CO1 | AB4: CO1 | AC4: CO2 | AD4: CO2 | AE4: CO2 | AF4: CO2 | AG4: CO2 | AH4: CO3 | AI4: CO3 | AJ4: CO3 | AK4: CO3 | AL4: CO3 | AM4: CO4 | AN4: CO4 | AO4: CO4 | AP4: CO4 | AQ4: CO4 | AR4: CO5 | AS4: CO5 | AT4: CO5 | AU4: CO5 | AV4: CO5 | AY4: CO1 | BA4: CO2 | BC4: CO3 | BE4: CO4 | BI4: CO1: Target Grade | BL4: C | BM4: CO2: Target Score | BP4: C | BQ4: CO3: Target Score | BT4: C | BU4: CO4: Target Score | BX4: C | BY4: CO5: Target Score | CB4: C
D5: T1Q1 | E5: T1Q2 | F5: T1Q3 | G5: T1Q7 | H5: A1 | I5: T1Q4 | J5: T1Q5 | K5: A3 | L5: A4 | P5: T1Q6 | T5: A2 | V5: Total | X5: Q1 | Y5: Q2 | Z5: Q3 | AC5: Q4 | AD5: Q8 | AH5: Q6 | AI5: Q7 | AJ5: Q9 | AM5: Q5 | AN5: Q10 | AW5: Total | AY5: Total marks | AZ5: Marks attained | BA5: Total marks | BB5: Marks attained | BC5: Total marks | BD5: Marks attained | BE5: Total marks | BF5: Marks attained | BI5: Total marks | BJ5: Marks attained | BK5: % Marks | BL5: Attained Status | BM5: Total marks | BN5: Marks attained | BO5: % Marks | BP5: Attained Status | BQ5: Total marks | BR5: Marks attained | BS5: % Marks | BT5: Attained Status | BU5: Total marks | BV5: Marks attained | BW5: % Marks | BX5: Attained Status | BY5: Total marks | BZ5: Marks attained | CA5: % Marks | CB5: Attained Status
C6: Total mark for the question | D6: 5 | E6: 5 | F6: 5 | G6: 5 | H6: 5 | I6: 5 | J6: 5 | K6: 5 | L6: 5 | P6: 5 | T6: 5 | V6: =SUM(D6:G6,I6:J6,P6)+(3*(H6+K6+L6+T6)/4) -> 50 | X6: 5 | Y6: 5 | Z6: 5 | AC6: 5 | AD6: 5 | AH6: 5 | AI6: 5 | AJ6: 5 | AM6: 5 | AN6: 5 | AW6: =SUM(X6:AV6) -> 50
A7: Sl.No. | B7: Roll No. | C7: Student Name | AY7: =SUM(D6:G6,X6:Z6,3*H6/4) -> 38.75 | BA7: =SUM(I6:J6,AC6:AD6,3*(K6+L6)/4) -> 27.5 | BC7: =SUM(P6,AH6:AJ6) -> 20 | BE7: =SUM(3*T6/4,AM6:AN6) -> 13.75 | BI7: =$AY$7 -> 38.75 | BM7: =$BA$7 -> 27.5 | BQ7: =$BC$7 -> 20 | BU7: =$BE$7 -> 13.75 | BY7: =#REF! -> #REF!
A8: 1 | D8: 2.5 | E8: 1 | F8: 1.5 | G8: 1.5 | H8: 4.75 | I8: 4 | J8: 2.5 | K8: 5 | L8: 4.75 | P8: 3 | T8: 5 | V8: =ROUND(SUM(D8:G8,I8:J8,P8)+(3*(H8+K8+L8+T8)/4),0) -> 31 | X8: 1.5 | Y8: 5 | Z8: 1.5 | AC8: 5 | AD8: 1 | AH8: 2.5 | AI8: 5 | AJ8: 5 | AM8: 1.5 | AN8: 1 | AW8: =SUM(X8:AV8) -> 29 | AZ8: =SUM(D8:G8,X8:Z8)+(3*H8/4) -> 18.0625 | BB8: =SUM(I8:J8,AC8:AD8)+(3*(K8+L8)/4) -> 19.8125 | BD8: =SUM(P8,AH8:AJ8) -> 15.5 | BF8: =AM8+AN8+T8*3/4 -> 6.25 | BI8: =$AY$7 -> 38.75 | BJ8: =AZ8 -> 18.0625 | BK8: =(BJ8/BI7)*100 -> 46.612903 | BL8: =IF(ROUNDUP(BK8,0)>='Front page'!$D$32,1,0) -> 0 | BM8: =$BA$7 -> 27.5 | BN8: =BB8 -> 19.8125 | BO8: =BN8/BM8*100 -> 72.045455 | BP8: =IF(ROUNDUP(BO8,0)>='Front page'!$D$32,1,0) -> 1 | BQ8: =$BC$7 -> 20 | BR8: =BD8 -> 15.5 | BS8: =BR8/BQ8*100 -> 77.5 | BT8: =IF(ROUNDUP(BS8,0)>='Front page'!$D$32,1,0) -> 1 | BU8: =$BE$7 -> 13.75 | BV8: =BF8 -> 6.25 | BW8: =BV8/BU8*100 -> 45.454545 | BX8: =IF(ROUNDUP(BW8,0)>='Front page'!$D$32,1,0) -> 0 | BY8: =#REF! -> #REF! | BZ8: =#REF! -> #REF! | CA8: =(BZ8/BY8)*100 -> #REF! | CB8: =IF(ROUNDUP(CA8,0)>='Front page'!$D$32,1,0) -> #REF!
A9: 2 | D9: 2 | E9: 1 | F9: 2.5 | G9: 1 | H9: 5 | I9: 4 | J9: 0.5 | K9: 4.75 | L9: 5 | P9: 4 | T9: 4.75 | V9: =ROUND(SUM(D9:G9,I9:J9,P9)+(3*(H9+K9+L9+T9)/4),0) -> 30 | X9: 1.5 | Y9: 5 | Z9: 2.5 | AC9: 1.5 | AD9: 2 | AH9: 3.5 | AI9: 3.5 | AJ9: 2 | AM9: 1.5 | AN9: 2 | AW9: =SUM(X9:AV9) -> 25 | AZ9: =SUM(D9:G9,X9:Z9)+(3*H9/4) -> 19.25 | BB9: =SUM(I9:J9,AC9:AD9)+(3*(K9+L9)/4) -> 15.3125 | BD9: =SUM(P9,AH9:AJ9) -> 13 | BF9: =AM9+AN9+T9*3/4 -> 7.0625 | BI9: =$AY$7 -> 38.75 | BJ9: =AZ9 -> 19.25 | BK9: =(BJ9/BI8)*100 -> 49.677419 | BL9: =IF(ROUNDUP(BK9,0)>='Front page'!$D$32,1,0) -> 1 | BM9: =$BA$7 -> 27.5 | BN9: =BB9 -> 15.3125 | BO9: =BN9/BM9*100 -> 55.681818 | BP9: =IF(ROUNDUP(BO9,0)>='Front page'!$D$32,1,0) -> 1 | BQ9: =$BC$7 -> 20 | BR9: =BD9 -> 13 | BS9: =BR9/BQ9*100 -> 65 | BT9: =IF(ROUNDUP(BS9,0)>='Front page'!$D$32,1,0) -> 1 | BU9: =$BE$7 -> 13.75 | BV9: =BF9 -> 7.0625 | BW9: =BV9/BU9*100 -> 51.363636 | BX9: =IF(ROUNDUP(BW9,0)>='Front page'!$D$32,1,0) -> 1 | BY9: =#REF! -> #REF! | BZ9: =#REF! -> #REF! | CA9: =(BZ9/BY9)*100 -> #REF! | CB9: =IF(ROUNDUP(CA9,0)>='Front page'!$D$32,1,0) -> #REF!
A10: 3 | D10: 0 | E10: 0 | F10: 1 | G10: 0 | H10: 4.5 | I10: 0 | J10: 1 | K10: 4.5 | L10: 4.5 | P10: 2 | T10: 4 | V10: =ROUND(SUM(D10:G10,I10:J10,P10)+(3*(H10+K10+L10+T10)/4),0) -> 17 | X10: 1.5 | Y10: 1.5 | Z10: 2 | AC10: 2 | AD10: 0 | AH10: 3 | AI10: 3.5 | AJ10: 0 | AM10: 3 | AN10: 1.5 | AW10: =SUM(X10:AV10) -> 18 | AZ10: =SUM(D10:G10,X10:Z10)+(3*H10/4) -> 9.375 | BB10: =SUM(I10:J10,AC10:AD10)+(3*(K10+L10)/4) -> 9.75 | BD10: =SUM(P10,AH10:AJ10) -> 8.5 | BF10: =AM10+AN10+T10*3/4 -> 7.5 | BI10: =$AY$7 -> 38.75 | BJ10: =AZ10 -> 9.375 | BK10: =(BJ10/BI9)*100 -> 24.193548 | BL10: =IF(ROUNDUP(BK10,0)>='Front page'!$D$32,1,0) -> 0 | BM10: =$BA$7 -> 27.5 | BN10: =BB10 -> 9.75 | BO10: =BN10/BM10*100 -> 35.454545 | BP10: =IF(ROUNDUP(BO10,0)>='Front page'!$D$32,1,0) -> 0 | BQ10: =$BC$7 -> 20 | BR10: =BD10 -> 8.5 | BS10: =BR10/BQ10*100 -> 42.5 | BT10: =IF(ROUNDUP(BS10,0)>='Front page'!$D$32,1,0) -> 0 | BU10: =$BE$7 -> 13.75 | BV10: =BF10 -> 7.5 | BW10: =BV10/BU10*100 -> 54.545455 | BX10: =IF(ROUNDUP(BW10,0)>='Front page'!$D$32,1,0) -> 1 | BY10: =#REF! -> #REF! | BZ10: =#REF! -> #REF! | CA10: =(BZ10/BY10)*100 -> #REF! | CB10: =IF(ROUNDUP(CA10,0)>='Front page'!$D$32,1,0) -> #REF!
A11: 4 | D11: 4 | E11: 5 | F11: 4 | G11: 5 | H11: 5 | I11: 1.5 | J11: 2 | K11: 5 | L11: 5 | P11: 4.5 | T11: 4 | V11: =ROUND(SUM(D11:G11,I11:J11,P11)+(3*(H11+K11+L11+T11)/4),0) -> 40 | X11: 3.5 | Y11: 3.5 | Z11: 0 | AC11: 5 | AD11: 3.5 | AH11: 3.5 | AI11: 4 | AJ11: 5 | AM11: 3.5 | AN11: 3.5 | AW11: =SUM(X11:AV11) -> 35 | AZ11: =SUM(D11:G11,X11:Z11)+(3*H11/4) -> 28.75 | BB11: =SUM(I11:J11,AC11:AD11)+(3*(K11+L11)/4) -> 19.5 | BD11: =SUM(P11,AH11:AJ11) -> 17 | BF11: =AM11+AN11+T11*3/4 -> 10 | BI11: =$AY$7 -> 38.75 | BJ11: =AZ11 -> 28.75 | BK11: =(BJ11/BI10)*100 -> 74.193548 | BL11: =IF(ROUNDUP(BK11,0)>='Front page'!$D$32,1,0) -> 1 | BM11: =$BA$7 -> 27.5 | BN11: =BB11 -> 19.5 | BO11: =BN11/BM11*100 -> 70.909091 | BP11: =IF(ROUNDUP(BO11,0)>='Front page'!$D$32,1,0) -> 1 | BQ11: =$BC$7 -> 20 | BR11: =BD11 -> 17 | BS11: =BR11/BQ11*100 -> 85 | BT11: =IF(ROUNDUP(BS11,0)>='Front page'!$D$32,1,0) -> 1 | BU11: =$BE$7 -> 13.75 | BV11: =BF11 -> 10 | BW11: =BV11/BU11*100 -> 72.727273 | BX11: =IF(ROUNDUP(BW11,0)>='Front page'!$D$32,1,0) -> 1 | BY11: =#REF! -> #REF! | BZ11: =#REF! -> #REF! | CA11: =(BZ11/BY11)*100 -> #REF! | CB11: =IF(ROUNDUP(CA11,0)>='Front page'!$D$32,1,0) -> #REF!
A12: 5 | D12: 2.5 | E12: 1 | F12: 2 | G12: 1.5 | H12: 4.5 | I12: 1 | J12: 1 | K12: 5 | L12: 5 | P12: 4 | T12: 4.5 | V12: =ROUND(SUM(D12:G12,I12:J12,P12)+(3*(H12+K12+L12+T12)/4),0) -> 27 | X12: 0 | Y12: 0.5 | Z12: 0.5 | AC12: 2 | AD12: 3.5 | AH12: 3.5 | AI12: 4 | AJ12: 2.5 | AM12: 0 | AN12: 3.5 | AW12: =SUM(X12:AV12) -> 20 | AZ12: =SUM(D12:G12,X12:Z12)+(3*H12/4) -> 11.375 | BB12: =SUM(I12:J12,AC12:AD12)+(3*(K12+L12)/4) -> 15 | BD12: =SUM(P12,AH12:AJ12) -> 14 | BF12: =AM12+AN12+T12*3/4 -> 6.875 | BI12: =$AY$7 -> 38.75 | BJ12: =AZ12 -> 11.375 | BK12: =(BJ12/BI11)*100 -> 29.354839 | BL12: =IF(ROUNDUP(BK12,0)>='Front page'!$D$32,1,0) -> 0 | BM12: =$BA$7 -> 27.5 | BN12: =BB12 -> 15 | BO12: =BN12/BM12*100 -> 54.545455 | BP12: =IF(ROUNDUP(BO12,0)>='Front page'!$D$32,1,0) -> 1 | BQ12: =$BC$7 -> 20 | BR12: =BD12 -> 14 | BS12: =BR12/BQ12*100 -> 70 | BT12: =IF(ROUNDUP(BS12,0)>='Front page'!$D$32,1,0) -> 1 | BU12: =$BE$7 -> 13.75 | BV12: =BF12 -> 6.875 | BW12: =BV12/BU12*100 -> 50 | BX12: =IF(ROUNDUP(BW12,0)>='Front page'!$D$32,1,0) -> 1 | BY12: =#REF! -> #REF! | BZ12: =#REF! -> #REF! | CA12: =(BZ12/BY12)*100 -> #REF! | CB12: =IF(ROUNDUP(CA12,0)>='Front page'!$D$32,1,0) -> #REF!
A13: 6 | D13: 2 | E13: 2 | F13: 0 | G13: 0 | H13: 4.5 | I13: 1.5 | J13: 2 | K13: 4 | L13: 5 | P13: 2.5 | T13: 4 | V13: =ROUND(SUM(D13:G13,I13:J13,P13)+(3*(H13+K13+L13+T13)/4),0) -> 23 | X13: 0 | Y13: 1 | Z13: 0 | AC13: 2.5 | AD13: 1.5 | AH13: 3.5 | AI13: 4 | AJ13: 0 | AM13: 2.5 | AN13: 2 | AW13: =SUM(X13:AV13) -> 17 | AZ13: =SUM(D13:G13,X13:Z13)+(3*H13/4) -> 8.375 | BB13: =SUM(I13:J13,AC13:AD13)+(3*(K13+L13)/4) -> 14.25 | BD13: =SUM(P13,AH13:AJ13) -> 10 | BF13: =AM13+AN13+T13*3/4 -> 7.5 | BI13: =$AY$7 -> 38.75 | BJ13: =AZ13 -> 8.375 | BK13: =(BJ13/BI12)*100 -> 21.612903 | BL13: =IF(ROUNDUP(BK13,0)>='Front page'!$D$32,1,0) -> 0 | BM13: =$BA$7 -> 27.5 | BN13: =BB13 -> 14.25 | BO13: =BN13/BM13*100 -> 51.818182 | BP13: =IF(ROUNDUP(BO13,0)>='Front page'!$D$32,1,0) -> 1 | BQ13: =$BC$7 -> 20 | BR13: =BD13 -> 10 | BS13: =BR13/BQ13*100 -> 50 | BT13: =IF(ROUNDUP(BS13,0)>='Front page'!$D$32,1,0) -> 1 | BU13: =$BE$7 -> 13.75 | BV13: =BF13 -> 7.5 | BW13: =BV13/BU13*100 -> 54.545455 | BX13: =IF(ROUNDUP(BW13,0)>='Front page'!$D$32,1,0) -> 1 | BY13: =#REF! -> #REF! | BZ13: =#REF! -> #REF! | CA13: =(BZ13/BY13)*100 -> #REF! | CB13: =IF(ROUNDUP(CA13,0)>='Front page'!$D$32,1,0) -> #REF!
A14: 7 | D14: 4 | E14: 0 | F14: 5 | G14: 1.5 | H14: 4.5 | I14: 4 | J14: 3 | K14: 4 | L14: 5 | P14: 4.5 | T14: 5 | V14: =ROUND(SUM(D14:G14,I14:J14,P14)+(3*(H14+K14+L14+T14)/4),0) -> 36 | X14: 1.5 | Y14: 5 | Z14: 1 | AC14: 5 | AD14: 3.5 | AH14: 3.5 | AI14: 5 | AJ14: 5 | AM14: 3.5 | AN14: 2 | AW14: =SUM(X14:AV14) -> 35 | AZ14: =SUM(D14:G14,X14:Z14)+(3*H14/4) -> 21.375 | BB14: =SUM(I14:J14,AC14:AD14)+(3*(K14+L14)/4) -> 22.25 | BD14: =SUM(P14,AH14:AJ14) -> 18 | BF14: =AM14+AN14+T14*3/4 -> 9.25 | BI14: =$AY$7 -> 38.75 | BJ14: =AZ14 -> 21.375 | BK14: =(BJ14/BI13)*100 -> 55.16129 | BL14: =IF(ROUNDUP(BK14,0)>='Front page'!$D$32,1,0) -> 1 | BM14: =$BA$7 -> 27.5 | BN14: =BB14 -> 22.25 | BO14: =BN14/BM14*100 -> 80.909091 | BP14: =IF(ROUNDUP(BO14,0)>='Front page'!$D$32,1,0) -> 1 | BQ14: =$BC$7 -> 20 | BR14: =BD14 -> 18 | BS14: =BR14/BQ14*100 -> 90 | BT14: =IF(ROUNDUP(BS14,0)>='Front page'!$D$32,1,0) -> 1 | BU14: =$BE$7 -> 13.75 | BV14: =BF14 -> 9.25 | BW14: =BV14/BU14*100 -> 67.272727 | BX14: =IF(ROUNDUP(BW14,0)>='Front page'!$D$32,1,0) -> 1 | BY14: =#REF! -> #REF! | BZ14: =#REF! -> #REF! | CA14: =(BZ14/BY14)*100 -> #REF! | CB14: =IF(ROUNDUP(CA14,0)>='Front page'!$D$32,1,0) -> #REF!
A15: 8 | D15: 5 | E15: 1.5 | F15: 4.5 | G15: 0 | H15: 4 | I15: 5 | J15: 0 | K15: 4 | L15: 4 | P15: 1 | T15: 5 | V15: =ROUND(SUM(D15:G15,I15:J15,P15)+(3*(H15+K15+L15+T15)/4),0) -> 30 | X15: 4 | Y15: 3.5 | Z15: 0 | AC15: 2.5 | AD15: 2.5 | AH15: 1.5 | AI15: 2 | AJ15: 2.5 | AM15: 1.5 | AN15: 0 | AW15: =SUM(X15:AV15) -> 20 | AZ15: =SUM(D15:G15,X15:Z15)+(3*H15/4) -> 21.5 | BB15: =SUM(I15:J15,AC15:AD15)+(3*(K15+L15)/4) -> 16 | BD15: =SUM(P15,AH15:AJ15) -> 7 | BF15: =AM15+AN15+T15*3/4 -> 5.25 | BI15: =$AY$7 -> 38.75 | BJ15: =AZ15 -> 21.5 | BK15: =(BJ15/BI14)*100 -> 55.483871 | BL15: =IF(ROUNDUP(BK15,0)>='Front page'!$D$32,1,0) -> 1 | BM15: =$BA$7 -> 27.5 | BN15: =BB15 -> 16 | BO15: =BN15/BM15*100 -> 58.181818 | BP15: =IF(ROUNDUP(BO15,0)>='Front page'!$D$32,1,0) -> 1 | BQ15: =$BC$7 -> 20 | BR15: =BD15 -> 7 | BS15: =BR15/BQ15*100 -> 35 | BT15: =IF(ROUNDUP(BS15,0)>='Front page'!$D$32,1,0) -> 0 | BU15: =$BE$7 -> 13.75 | BV15: =BF15 -> 5.25 | BW15: =BV15/BU15*100 -> 38.181818 | BX15: =IF(ROUNDUP(BW15,0)>='Front page'!$D$32,1,0) -> 0 | BY15: =#REF! -> #REF! | BZ15: =#REF! -> #REF! | CA15: =(BZ15/BY15)*100 -> #REF! | CB15: =IF(ROUNDUP(CA15,0)>='Front page'!$D$32,1,0) -> #REF!
A16: 9 | D16: 4 | E16: 3 | F16: 5 | G16: 5 | H16: 5 | I16: 5 | J16: 4 | K16: 5 | L16: 5 | P16: 4 | T16: 5 | V16: =ROUND(SUM(D16:G16,I16:J16,P16)+(3*(H16+K16+L16+T16)/4),0) -> 45 | X16: 5 | Y16: 5 | Z16: 3 | AC16: 5 | AD16: 4 | AH16: 3.5 | AI16: 4 | AJ16: 5 | AM16: 4 | AN16: 2.5 | AW16: =SUM(X16:AV16) -> 41 | AZ16: =SUM(D16:G16,X16:Z16)+(3*H16/4) -> 33.75 | BB16: =SUM(I16:J16,AC16:AD16)+(3*(K16+L16)/4) -> 25.5 | BD16: =SUM(P16,AH16:AJ16) -> 16.5 | BF16: =AM16+AN16+T16*3/4 -> 10.25 | BI16: =$AY$7 -> 38.75 | BJ16: =AZ16 -> 33.75 | BK16: =(BJ16/BI15)*100 -> 87.096774 | BL16: =IF(ROUNDUP(BK16,0)>='Front page'!$D$32,1,0) -> 1 | BM16: =$BA$7 -> 27.5 | BN16: =BB16 -> 25.5 | BO16: =BN16/BM16*100 -> 92.727273 | BP16: =IF(ROUNDUP(BO16,0)>='Front page'!$D$32,1,0) -> 1 | BQ16: =$BC$7 -> 20 | BR16: =BD16 -> 16.5 | BS16: =BR16/BQ16*100 -> 82.5 | BT16: =IF(ROUNDUP(BS16,0)>='Front page'!$D$32,1,0) -> 1 | BU16: =$BE$7 -> 13.75 | BV16: =BF16 -> 10.25 | BW16: =BV16/BU16*100 -> 74.545455 | BX16: =IF(ROUNDUP(BW16,0)>='Front page'!$D$32,1,0) -> 1 | BY16: =#REF! -> #REF! | BZ16: =#REF! -> #REF! | CA16: =(BZ16/BY16)*100 -> #REF! | CB16: =IF(ROUNDUP(CA16,0)>='Front page'!$D$32,1,0) -> #REF!
A17: 10 | D17: 4 | E17: 1.5 | F17: 3 | G17: 1.5 | H17: 5 | I17: 1 | J17: 2 | K17: 5 | L17: 5 | P17: 4 | T17: 5 | V17: =ROUND(SUM(D17:G17,I17:J17,P17)+(3*(H17+K17+L17+T17)/4),0) -> 32 | X17: 1 | Y17: 5 | Z17: 4 | AC17: 4 | AD17: 4 | AH17: 4 | AI17: 5 | AJ17: 5 | AM17: 4 | AN17: 3 | AW17: =SUM(X17:AV17) -> 39 | AZ17: =SUM(D17:G17,X17:Z17)+(3*H17/4) -> 23.75 | BB17: =SUM(I17:J17,AC17:AD17)+(3*(K17+L17)/4) -> 18.5 | BD17: =SUM(P17,AH17:AJ17) -> 18 | BF17: =AM17+AN17+T17*3/4 -> 10.75 | BI17: =$AY$7 -> 38.75 | BJ17: =AZ17 -> 23.75 | BK17: =(BJ17/BI16)*100 -> 61.290323 | BL17: =IF(ROUNDUP(BK17,0)>='Front page'!$D$32,1,0) -> 1 | BM17: =$BA$7 -> 27.5 | BN17: =BB17 -> 18.5 | BO17: =BN17/BM17*100 -> 67.272727 | BP17: =IF(ROUNDUP(BO17,0)>='Front page'!$D$32,1,0) -> 1 | BQ17: =$BC$7 -> 20 | BR17: =BD17 -> 18 | BS17: =BR17/BQ17*100 -> 90 | BT17: =IF(ROUNDUP(BS17,0)>='Front page'!$D$32,1,0) -> 1 | BU17: =$BE$7 -> 13.75 | BV17: =BF17 -> 10.75 | BW17: =BV17/BU17*100 -> 78.181818 | BX17: =IF(ROUNDUP(BW17,0)>='Front page'!$D$32,1,0) -> 1 | BY17: =#REF! -> #REF! | BZ17: =#REF! -> #REF! | CA17: =(BZ17/BY17)*100 -> #REF! | CB17: =IF(ROUNDUP(CA17,0)>='Front page'!$D$32,1,0) -> #REF!
A18: 11 | D18: 2.5 | E18: 1 | F18: 3 | G18: 1.5 | H18: 5 | I18: 1 | J18: 1.5 | K18: 5 | L18: 5 | P18: 3.5 | T18: 5 | V18: =ROUND(SUM(D18:G18,I18:J18,P18)+(3*(H18+K18+L18+T18)/4),0) -> 29 | X18: 1.5 | Y18: 5 | Z18: 2 | AC18: 3 | AD18: 4 | AH18: 4 | AI18: 3.5 | AJ18: 5 | AM18: 5 | AN18: 3 | AW18: =SUM(X18:AV18) -> 36 | AZ18: =SUM(D18:G18,X18:Z18)+(3*H18/4) -> 20.25 | BB18: =SUM(I18:J18,AC18:AD18)+(3*(K18+L18)/4) -> 17 | BD18: =SUM(P18,AH18:AJ18) -> 16 | BF18: =AM18+AN18+T18*3/4 -> 11.75 | BI18: =$AY$7 -> 38.75 | BJ18: =AZ18 -> 20.25 | BK18: =(BJ18/BI17)*100 -> 52.258065 | BL18: =IF(ROUNDUP(BK18,0)>='Front page'!$D$32,1,0) -> 1 | BM18: =$BA$7 -> 27.5 | BN18: =BB18 -> 17 | BO18: =BN18/BM18*100 -> 61.818182 | BP18: =IF(ROUNDUP(BO18,0)>='Front page'!$D$32,1,0) -> 1 | BQ18: =$BC$7 -> 20 | BR18: =BD18 -> 16 | BS18: =BR18/BQ18*100 -> 80 | BT18: =IF(ROUNDUP(BS18,0)>='Front page'!$D$32,1,0) -> 1 | BU18: =$BE$7 -> 13.75 | BV18: =BF18 -> 11.75 | BW18: =BV18/BU18*100 -> 85.454545 | BX18: =IF(ROUNDUP(BW18,0)>='Front page'!$D$32,1,0) -> 1 | BY18: =#REF! -> #REF! | BZ18: =#REF! -> #REF! | CA18: =(BZ18/BY18)*100 -> #REF! | CB18: =IF(ROUNDUP(CA18,0)>='Front page'!$D$32,1,0) -> #REF!
A19: 12 | D19: 2.5 | E19: 0 | F19: 3 | G19: 1.5 | H19: 5 | I19: 5 | J19: 2 | K19: 5 | L19: 5 | P19: 3 | T19: 5 | V19: =ROUND(SUM(D19:G19,I19:J19,P19)+(3*(H19+K19+L19+T19)/4),0) -> 32 | X19: 0 | Y19: 5 | Z19: 5 | AC19: 5 | AD19: 2.5 | AH19: 4 | AI19: 5 | AJ19: 5 | AM19: 2 | AN19: 2.5 | AW19: =SUM(X19:AV19) -> 36 | AZ19: =SUM(D19:G19,X19:Z19)+(3*H19/4) -> 20.75 | BB19: =SUM(I19:J19,AC19:AD19)+(3*(K19+L19)/4) -> 22 | BD19: =SUM(P19,AH19:AJ19) -> 17 | BF19: =AM19+AN19+T19*3/4 -> 8.25 | BI19: =$AY$7 -> 38.75 | BJ19: =AZ19 -> 20.75 | BK19: =(BJ19/BI18)*100 -> 53.548387 | BL19: =IF(ROUNDUP(BK19,0)>='Front page'!$D$32,1,0) -> 1 | BM19: =$BA$7 -> 27.5 | BN19: =BB19 -> 22 | BO19: =BN19/BM19*100 -> 80 | BP19: =IF(ROUNDUP(BO19,0)>='Front page'!$D$32,1,0) -> 1 | BQ19: =$BC$7 -> 20 | BR19: =BD19 -> 17 | BS19: =BR19/BQ19*100 -> 85 | BT19: =IF(ROUNDUP(BS19,0)>='Front page'!$D$32,1,0) -> 1 | BU19: =$BE$7 -> 13.75 | BV19: =BF19 -> 8.25 | BW19: =BV19/BU19*100 -> 60 | BX19: =IF(ROUNDUP(BW19,0)>='Front page'!$D$32,1,0) -> 1 | BY19: =#REF! -> #REF! | BZ19: =#REF! -> #REF! | CA19: =(BZ19/BY19)*100 -> #REF! | CB19: =IF(ROUNDUP(CA19,0)>='Front page'!$D$32,1,0) -> #REF!
... A34: 27 | D34: 2.5 | E34: 0 | F34: 0 | G34: 0 | H34: 5 | I34: 4 | J34: 2.5 | K34: 5 | L34: 4 | P34: 2 | T34: 4 | V34: =ROUND(SUM(D34:G34,I34:J34,P34)+(3*(H34+K34+L34+T34)/4),0) -> 25 | X34: 1 | Y34: 1 | Z34: 0.5 | AC34: 1 | AD34: 3 | AH34: 3 | AI34: 2.5 | AJ34: 2.5 | AM34: 0 | AN34: 1.5 | AW34: =SUM(X34:AV34) -> 16 | AZ34: =SUM(D34:G34,X34:Z34)+(3*H34/4) -> 8.75 | BB34: =SUM(I34:J34,AC34:AD34)+(3*(K34+L34)/4) -> 17.25 | BD34: =SUM(P34,AH34:AJ34) -> 10 | BF34: =AM34+AN34+T34*3/4 -> 4.5 | BI34: =$AY$7 -> 38.75 | BJ34: =AZ34 -> 8.75 | BK34: =(BJ34/BI33)*100 -> 22.580645 | BL34: =IF(ROUNDUP(BK34,0)>='Front page'!$D$32,1,0) -> 0 | BM34: =$BA$7 -> 27.5 | BN34: =BB34 -> 17.25 | BO34: =BN34/BM34*100 -> 62.727273 | BP34: =IF(ROUNDUP(BO34,0)>='Front page'!$D$32,1,0) -> 1 | BQ34: =$BC$7 -> 20 | BR34: =BD34 -> 10 | BS34: =BR34/BQ34*100 -> 50 | BT34: =IF(ROUNDUP(BS34,0)>='Front page'!$D$32,1,0) -> 1 | BU34: =$BE$7 -> 13.75 | BV34: =BF34 -> 4.5 | BW34: =BV34/BU34*100 -> 32.727273 | BX34: =IF(ROUNDUP(BW34,0)>='Front page'!$D$32,1,0) -> 0 | BY34: =#REF! -> #REF! | BZ34: =#REF! -> #REF! | CA34: =(BZ34/BY34)*100 -> #REF! | CB34: =IF(ROUNDUP(CA34,0)>='Front page'!$D$32,1,0) -> #REF!
A35: 28 | V35: =SUM(D35:U35) -> 0 | AZ35: =SUM(D35:H35) -> 0 | BB35: =SUM(I35:O35) -> 0 | BD35: =SUM(P35:S35) -> 0 | BF35: =SUM(T35:U35) -> 0 | BI35: =$AY$7 -> 38.75 | BJ35: =AZ35 -> 0 | BK35: =(BJ35/BI33)*100 -> 0 | BL35: =IF(BK35>=$BL$4,1,0) -> 0 | BM35: =$BA$7 -> 27.5 | BN35: =BB35 -> 0 | BO35: =BN35/BM35*100 -> 0 | BP35: =IF(BO35>=60,1,0) -> 0 | BQ35: =$BC$7 -> 20 | BR35: =BD35 -> 0 | BS35: =BR35/BQ35*100 -> 0 | BT35: =IF(BS35>=60,1,0) -> 0 | BU35: =$BE$7 -> 13.75 | BV35: =BF35 -> 0 | BW35: =BV35/BU35*100 -> 0 | BX35: =IF(BW35>=60,1,0) -> 0 | BY35: =#REF! -> #REF! | BZ35: =#REF! -> #REF! | CA35: =(BZ35/BY35)*100 -> #REF! | CB35: =IF(CA35>=60,1,0) -> #REF!
A36: 29 | V36: =SUM(D36:U36) -> 0 | AZ36: =SUM(D36:H36) -> 0 | BB36: =SUM(I36:O36) -> 0 | BD36: =SUM(P36:S36) -> 0 | BF36: =SUM(T36:U36) -> 0 | BI36: =$AY$7 -> 38.75 | BJ36: =AZ36 -> 0 | BK36: =(BJ36/BI33)*100 -> 0 | BL36: =IF(BK36>=$BL$4,1,0) -> 0 | BM36: =$BA$7 -> 27.5 | BN36: =BB36 -> 0 | BO36: =BN36/BM36*100 -> 0 | BP36: =IF(BO36>=60,1,0) -> 0 | BQ36: =$BC$7 -> 20 | BR36: =BD36 -> 0 | BS36: =BR36/BQ36*100 -> 0 | BT36: =IF(BS36>=60,1,0) -> 0 | BU36: =$BE$7 -> 13.75 | BV36: =BF36 -> 0 | BW36: =BV36/BU36*100 -> 0 | BX36: =IF(BW36>=60,1,0) -> 0 | BY36: =#REF! -> #REF! | BZ36: =#REF! -> #REF! | CA36: =(BZ36/BY36)*100 -> #REF! | CB36: =IF(CA36>=60,1,0) -> #REF!
A37: 30 | V37: =SUM(D37:U37) -> 0 | AZ37: =SUM(D37:H37) -> 0 | BB37: =SUM(I37:O37) -> 0 | BD37: =SUM(P37:S37) -> 0 | BF37: =SUM(T37:U37) -> 0 | BI37: =$AY$7 -> 38.75 | BJ37: =AZ37 -> 0 | BK37: =(BJ37/BI33)*100 -> 0 | BL37: =IF(BK37>=$BL$4,1,0) -> 0 | BM37: =$BA$7 -> 27.5 | BN37: =BB37 -> 0 | BO37: =BN37/BM37*100 -> 0 | BP37: =IF(BO37>=60,1,0) -> 0 | BQ37: =$BC$7 -> 20 | BR37: =BD37 -> 0 | BS37: =BR37/BQ37*100 -> 0 | BT37: =IF(BS37>=60,1,0) -> 0 | BU37: =$BE$7 -> 13.75 | BV37: =BF37 -> 0 | BW37: =BV37/BU37*100 -> 0 | BX37: =IF(BW37>=60,1,0) -> 0 | BY37: =#REF! -> #REF! | BZ37: =#REF! -> #REF! | CA37: =(BZ37/BY37)*100 -> #REF! | CB37: =IF(CA37>=60,1,0) -> #REF!
A38: 31 | V38: =SUM(D38:U38) -> 0 | AZ38: =SUM(D38:H38) -> 0 | BB38: =SUM(I38:O38) -> 0 | BD38: =SUM(P38:S38) -> 0 | BF38: =SUM(T38:U38) -> 0 | BI38: =$AY$7 -> 38.75 | BJ38: =AZ38 -> 0 | BK38: =(BJ38/BI37)*100 -> 0 | BL38: =IF(BK38>=$BL$4,1,0) -> 0 | BM38: =$BA$7 -> 27.5 | BN38: =BB38 -> 0 | BO38: =BN38/BM38*100 -> 0 | BP38: =IF(BO38>=60,1,0) -> 0 | BQ38: =$BC$7 -> 20 | BR38: =BD38 -> 0 | BS38: =BR38/BQ38*100 -> 0 | BT38: =IF(BS38>=60,1,0) -> 0 | BU38: =$BE$7 -> 13.75 | BV38: =BF38 -> 0 | BW38: =BV38/BU38*100 -> 0 | BX38: =IF(BW38>=60,1,0) -> 0 | BY38: =#REF! -> #REF! | BZ38: =#REF! -> #REF! | CA38: =(BZ38/BY38)*100 -> #REF! | CB38: =IF(CA38>=60,1,0) -> #REF!
A39: 32 | V39: =SUM(D39:U39) -> 0 | AZ39: =SUM(D39:H39) -> 0 | BB39: =SUM(I39:O39) -> 0 | BD39: =SUM(P39:S39) -> 0 | BF39: =SUM(T39:U39) -> 0 | BI39: =$AY$7 -> 38.75 | BJ39: =AZ39 -> 0 | BK39: =(BJ39/BI37)*100 -> 0 | BL39: =IF(BK39>=$BL$4,1,0) -> 0 | BM39: =$BA$7 -> 27.5 | BN39: =BB39 -> 0 | BO39: =BN39/BM39*100 -> 0 | BP39: =IF(BO39>=60,1,0) -> 0 | BQ39: =$BC$7 -> 20 | BR39: =BD39 -> 0 | BS39: =BR39/BQ39*100 -> 0 | BT39: =IF(BS39>=60,1,0) -> 0 | BU39: =$BE$7 -> 13.75 | BV39: =BF39 -> 0 | BW39: =BV39/BU39*100 -> 0 | BX39: =IF(BW39>=60,1,0) -> 0 | BY39: =#REF! -> #REF! | BZ39: =#REF! -> #REF! | CA39: =(BZ39/BY39)*100 -> #REF! | CB39: =IF(CA39>=60,1,0) -> #REF!
A40: 33 | V40: =SUM(D40:U40) -> 0 | AW40: =SUM(X40:AV40) -> 0 | AZ40: =SUM(D40:H40) -> 0 | BB40: =SUM(I40:O40) -> 0 | BD40: =SUM(P40:S40) -> 0 | BF40: =SUM(T40:U40) -> 0 | BI40: =$AY$7 -> 38.75 | BJ40: =AZ40 -> 0 | BK40: =(BJ40/BI37)*100 -> 0 | BL40: =IF(BK40>=$BL$4,1,0) -> 0 | BM40: =$BA$7 -> 27.5 | BN40: =BB40 -> 0 | BO40: =BN40/BM40*100 -> 0 | BP40: =IF(BO40>=60,1,0) -> 0 | BQ40: =$BC$7 -> 20 | BR40: =BD40 -> 0 | BS40: =BR40/BQ40*100 -> 0 | BT40: =IF(BS40>=60,1,0) -> 0 | BU40: =$BE$7 -> 13.75 | BV40: =BF40 -> 0 | BW40: =BV40/BU40*100 -> 0 | BX40: =IF(BW40>=60,1,0) -> 0 | BY40: =#REF! -> #REF! | BZ40: =#REF! -> #REF! | CA40: =(BZ40/BY40)*100 -> #REF! | CB40: =IF(CA40>=60,1,0) -> #REF!
A41: 34 | V41: =SUM(D41:U41) -> 0 | AW41: =SUM(X41:AV41) -> 0 | AZ41: =SUM(D41:H41) -> 0 | BB41: =SUM(I41:O41) -> 0 | BD41: =SUM(P41:S41) -> 0 | BF41: =SUM(T41:U41) -> 0 | BI41: =$AY$7 -> 38.75 | BJ41: =AZ41 -> 0 | BK41: =(BJ41/BI37)*100 -> 0 | BL41: =IF(BK41>=$BL$4,1,0) -> 0 | BM41: =$BA$7 -> 27.5 | BN41: =BB41 -> 0 | BO41: =BN41/BM41*100 -> 0 | BP41: =IF(BO41>=60,1,0) -> 0 | BQ41: =$BC$7 -> 20 | BR41: =BD41 -> 0 | BS41: =BR41/BQ41*100 -> 0 | BT41: =IF(BS41>=60,1,0) -> 0 | BU41: =$BE$7 -> 13.75 | BV41: =BF41 -> 0 | BW41: =BV41/BU41*100 -> 0 | BX41: =IF(BW41>=60,1,0) -> 0 | BY41: =#REF! -> #REF! | BZ41: =#REF! -> #REF! | CA41: =(BZ41/BY41)*100 -> #REF! | CB41: =IF(CA41>=60,1,0) -> #REF!
A42: 35 | V42: =SUM(D42:U42) -> 0 | AW42: =SUM(X42:AV42) -> 0 | AZ42: =SUM(D42:H42) -> 0 | BB42: =SUM(I42:O42) -> 0 | BD42: =SUM(P42:S42) -> 0 | BF42: =SUM(T42:U42) -> 0 | BI42: =$AY$7 -> 38.75 | BJ42: =AZ42 -> 0 | BK42: =(BJ42/BI41)*100 -> 0 | BL42: =IF(BK42>=$BL$4,1,0) -> 0 | BM42: =$BA$7 -> 27.5 | BN42: =BB42 -> 0 | BO42: =BN42/BM42*100 -> 0 | BP42: =IF(BO42>=60,1,0) -> 0 | BQ42: =$BC$7 -> 20 | BR42: =BD42 -> 0 | BS42: =BR42/BQ42*100 -> 0 | BT42: =IF(BS42>=60,1,0) -> 0 | BU42: =$BE$7 -> 13.75 | BV42: =BF42 -> 0 | BW42: =BV42/BU42*100 -> 0 | BX42: =IF(BW42>=60,1,0) -> 0 | BY42: =#REF! -> #REF! | BZ42: =#REF! -> #REF! | CA42: =(BZ42/BY42)*100 -> #REF! | CB42: =IF(CA42>=60,1,0) -> #REF!
A43: 36 | V43: =SUM(D43:U43) -> 0 | AW43: =SUM(X43:AV43) -> 0 | AZ43: =SUM(D43:H43) -> 0 | BB43: =SUM(I43:O43) -> 0 | BD43: =SUM(P43:S43) -> 0 | BF43: =SUM(T43:U43) -> 0 | BI43: =$AY$7 -> 38.75 | BJ43: =AZ43 -> 0 | BK43: =(BJ43/BI41)*100 -> 0 | BL43: =IF(BK43>=$BL$4,1,0) -> 0 | BM43: =$BA$7 -> 27.5 | BN43: =BB43 -> 0 | BO43: =BN43/BM43*100 -> 0 | BP43: =IF(BO43>=60,1,0) -> 0 | BQ43: =$BC$7 -> 20 | BR43: =BD43 -> 0 | BS43: =BR43/BQ43*100 -> 0 | BT43: =IF(BS43>=60,1,0) -> 0 | BU43: =$BE$7 -> 13.75 | BV43: =BF43 -> 0 | BW43: =BV43/BU43*100 -> 0 | BX43: =IF(BW43>=60,1,0) -> 0 | BY43: =#REF! -> #REF! | BZ43: =#REF! -> #REF! | CA43: =(BZ43/BY43)*100 -> #REF! | CB43: =IF(CA43>=60,1,0) -> #REF!
A44: 37 | V44: =SUM(D44:U44) -> 0 | AW44: =SUM(X44:AV44) -> 0 | AZ44: =SUM(D44:H44) -> 0 | BB44: =SUM(I44:O44) -> 0 | BD44: =SUM(P44:S44) -> 0 | BF44: =SUM(T44:U44) -> 0 | BI44: =$AY$7 -> 38.75 | BJ44: =AZ44 -> 0 | BK44: =(BJ44/BI41)*100 -> 0 | BL44: =IF(BK44>=$BL$4,1,0) -> 0 | BM44: =$BA$7 -> 27.5 | BN44: =BB44 -> 0 | BO44: =BN44/BM44*100 -> 0 | BP44: =IF(BO44>=60,1,0) -> 0 | BQ44: =$BC$7 -> 20 | BR44: =BD44 -> 0 | BS44: =BR44/BQ44*100 -> 0 | BT44: =IF(BS44>=60,1,0) -> 0 | BU44: =$BE$7 -> 13.75 | BV44: =BF44 -> 0 | BW44: =BV44/BU44*100 -> 0 | BX44: =IF(BW44>=60,1,0) -> 0 | BY44: =#REF! -> #REF! | BZ44: =#REF! -> #REF! | CA44: =(BZ44/BY44)*100 -> #REF! | CB44: =IF(CA44>=60,1,0) -> #REF!
A45: 38 | V45: =SUM(D45:U45) -> 0 | AW45: =SUM(X45:AV45) -> 0 | AZ45: =SUM(D45:H45) -> 0 | BB45: =SUM(I45:O45) -> 0 | BD45: =SUM(P45:S45) -> 0 | BF45: =SUM(T45:U45) -> 0 | BI45: =$AY$7 -> 38.75 | BJ45: =AZ45 -> 0 | BK45: =(BJ45/BI41)*100 -> 0 | BL45: =IF(BK45>=$BL$4,1,0) -> 0 | BM45: =$BA$7 -> 27.5 | BN45: =BB45 -> 0 | BO45: =BN45/BM45*100 -> 0 | BP45: =IF(BO45>=60,1,0) -> 0 | BQ45: =$BC$7 -> 20 | BR45: =BD45 -> 0 | BS45: =BR45/BQ45*100 -> 0 | BT45: =IF(BS45>=60,1,0) -> 0 | BU45: =$BE$7 -> 13.75 | BV45: =BF45 -> 0 | BW45: =BV45/BU45*100 -> 0 | BX45: =IF(BW45>=60,1,0) -> 0 | BY45: =#REF! -> #REF! | BZ45: =#REF! -> #REF! | CA45: =(BZ45/BY45)*100 -> #REF! | CB45: =IF(CA45>=60,1,0) -> #REF!
A46: 39 | V46: =SUM(D46:U46) -> 0 | AW46: =SUM(X46:AV46) -> 0 | AZ46: =SUM(D46:H46) -> 0 | BB46: =SUM(I46:O46) -> 0 | BD46: =SUM(P46:S46) -> 0 | BF46: =SUM(T46:U46) -> 0 | BI46: =$AY$7 -> 38.75 | BJ46: =AZ46 -> 0 | BK46: =(BJ46/BI45)*100 -> 0 | BL46: =IF(BK46>=$BL$4,1,0) -> 0 | BM46: =$BA$7 -> 27.5 | BN46: =BB46 -> 0 | BO46: =BN46/BM46*100 -> 0 | BP46: =IF(BO46>=60,1,0) -> 0 | BQ46: =$BC$7 -> 20 | BR46: =BD46 -> 0 | BS46: =BR46/BQ46*100 -> 0 | BT46: =IF(BS46>=60,1,0) -> 0 | BU46: =$BE$7 -> 13.75 | BV46: =BF46 -> 0 | BW46: =BV46/BU46*100 -> 0 | BX46: =IF(BW46>=60,1,0) -> 0 | BY46: =#REF! -> #REF! | BZ46: =#REF! -> #REF! | CA46: =(BZ46/BY46)*100 -> #REF! | CB46: =IF(CA46>=60,1,0) -> #REF!
A47: 40 | V47: =SUM(D47:U47) -> 0 | AW47: =SUM(X47:AV47) -> 0 | AZ47: =SUM(D47:H47) -> 0 | BB47: =SUM(I47:O47) -> 0 | BD47: =SUM(P47:S47) -> 0 | BF47: =SUM(T47:U47) -> 0 | BI47: =$AY$7 -> 38.75 | BJ47: =AZ47 -> 0 | BK47: =(BJ47/BI45)*100 -> 0 | BL47: =IF(BK47>=$BL$4,1,0) -> 0 | BM47: =$BA$7 -> 27.5 | BN47: =BB47 -> 0 | BO47: =BN47/BM47*100 -> 0 | BP47: =IF(BO47>=60,1,0) -> 0 | BQ47: =$BC$7 -> 20 | BR47: =BD47 -> 0 | BS47: =BR47/BQ47*100 -> 0 | BT47: =IF(BS47>=60,1,0) -> 0 | BU47: =$BE$7 -> 13.75 | BV47: =BF47 -> 0 | BW47: =BV47/BU47*100 -> 0 | BX47: =IF(BW47>=60,1,0) -> 0 | BY47: =#REF! -> #REF! | BZ47: =#REF! -> #REF! | CA47: =(BZ47/BY47)*100 -> #REF! | CB47: =IF(CA47>=60,1,0) -> #REF!
A48: 41 | V48: =SUM(D48:U48) -> 0 | AW48: =SUM(X48:AV48) -> 0 | AZ48: =SUM(D48:H48) -> 0 | BB48: =SUM(I48:O48) -> 0 | BD48: =SUM(P48:S48) -> 0 | BF48: =SUM(T48:U48) -> 0 | BI48: =$AY$7 -> 38.75 | BJ48: =AZ48 -> 0 | BK48: =(BJ48/BI45)*100 -> 0 | BL48: =IF(BK48>=$BL$4,1,0) -> 0 | BM48: =$BA$7 -> 27.5 | BN48: =BB48 -> 0 | BO48: =BN48/BM48*100 -> 0 | BP48: =IF(BO48>=60,1,0) -> 0 | BQ48: =$BC$7 -> 20 | BR48: =BD48 -> 0 | BS48: =BR48/BQ48*100 -> 0 | BT48: =IF(BS48>=60,1,0) -> 0 | BU48: =$BE$7 -> 13.75 | BV48: =BF48 -> 0 | BW48: =BV48/BU48*100 -> 0 | BX48: =IF(BW48>=60,1,0) -> 0 | BY48: =#REF! -> #REF! | BZ48: =#REF! -> #REF! | CA48: =(BZ48/BY48)*100 -> #REF! | CB48: =IF(CA48>=60,1,0) -> #REF!
A49: 42 | V49: =SUM(D49:U49) -> 0 | AW49: =SUM(X49:AV49) -> 0 | AZ49: =SUM(D49:H49) -> 0 | BB49: =SUM(I49:O49) -> 0 | BD49: =SUM(P49:S49) -> 0 | BF49: =SUM(T49:U49) -> 0 | BI49: =$AY$7 -> 38.75 | BJ49: =AZ49 -> 0 | BK49: =(BJ49/BI46)*100 -> 0 | BL49: =IF(BK49>=$BL$4,1,0) -> 0 | BM49: =$BA$7 -> 27.5 | BN49: =BB49 -> 0 | BO49: =BN49/BM49*100 -> 0 | BP49: =IF(BO49>=60,1,0) -> 0 | BQ49: =$BC$7 -> 20 | BR49: =BD49 -> 0 | BS49: =BR49/BQ49*100 -> 0 | BT49: =IF(BS49>=60,1,0) -> 0 | BU49: =$BE$7 -> 13.75 | BV49: =BF49 -> 0 | BW49: =BV49/BU49*100 -> 0 | BX49: =IF(BW49>=60,1,0) -> 0 | BY49: =#REF! -> #REF! | BZ49: =#REF! -> #REF! | CA49: =(BZ49/BY49)*100 -> #REF! | CB49: =IF(CA49>=60,1,0) -> #REF!
A50: 43 | V50: =SUM(D50:U50) -> 0 | AW50: =SUM(X50:AV50) -> 0 | AZ50: =SUM(D50:H50) -> 0 | BB50: =SUM(I50:O50) -> 0 | BD50: =SUM(P50:S50) -> 0 | BF50: =SUM(T50:U50) -> 0 | BI50: =$AY$7 -> 38.75 | BJ50: =AZ50 -> 0 | BK50: =(BJ50/BI47)*100 -> 0 | BL50: =IF(BK50>=$BL$4,1,0) -> 0 | BM50: =$BA$7 -> 27.5 | BN50: =BB50 -> 0 | BO50: =BN50/BM50*100 -> 0 | BP50: =IF(BO50>=60,1,0) -> 0 | BQ50: =$BC$7 -> 20 | BR50: =BD50 -> 0 | BS50: =BR50/BQ50*100 -> 0 | BT50: =IF(BS50>=60,1,0) -> 0 | BU50: =$BE$7 -> 13.75 | BV50: =BF50 -> 0 | BW50: =BV50/BU50*100 -> 0 | BX50: =IF(BW50>=60,1,0) -> 0 | BY50: =#REF! -> #REF! | BZ50: =#REF! -> #REF! | CA50: =(BZ50/BY50)*100 -> #REF! | CB50: =IF(CA50>=60,1,0) -> #REF!
A51: 44 | V51: =SUM(D51:U51) -> 0 | AW51: =SUM(X51:AV51) -> 0 | AZ51: =SUM(D51:H51) -> 0 | BB51: =SUM(I51:O51) -> 0 | BD51: =SUM(P51:S51) -> 0 | BF51: =SUM(T51:U51) -> 0 | BI51: =$AY$7 -> 38.75 | BJ51: =AZ51 -> 0 | BK51: =(BJ51/BI48)*100 -> 0 | BL51: =IF(BK51>=$BL$4,1,0) -> 0 | BM51: =$BA$7 -> 27.5 | BN51: =BB51 -> 0 | BO51: =BN51/BM51*100 -> 0 | BP51: =IF(BO51>=60,1,0) -> 0 | BQ51: =$BC$7 -> 20 | BR51: =BD51 -> 0 | BS51: =BR51/BQ51*100 -> 0 | BT51: =IF(BS51>=60,1,0) -> 0 | BU51: =$BE$7 -> 13.75 | BV51: =BF51 -> 0 | BW51: =BV51/BU51*100 -> 0 | BX51: =IF(BW51>=60,1,0) -> 0 | BY51: =#REF! -> #REF! | BZ51: =#REF! -> #REF! | CA51: =(BZ51/BY51)*100 -> #REF! | CB51: =IF(CA51>=60,1,0) -> #REF!
A52: 45 | V52: =SUM(D52:U52) -> 0 | AW52: =SUM(X52:AV52) -> 0 | AZ52: =SUM(D52:H52) -> 0 | BB52: =SUM(I52:O52) -> 0 | BD52: =SUM(P52:S52) -> 0 | BF52: =SUM(T52:U52) -> 0 | BI52: =$AY$7 -> 38.75 | BJ52: =AZ52 -> 0 | BK52: =(BJ52/BI49)*100 -> 0 | BL52: =IF(BK52>=$BL$4,1,0) -> 0 | BM52: =$BA$7 -> 27.5 | BN52: =BB52 -> 0 | BO52: =BN52/BM52*100 -> 0 | BP52: =IF(BO52>=60,1,0) -> 0 | BQ52: =$BC$7 -> 20 | BR52: =BD52 -> 0 | BS52: =BR52/BQ52*100 -> 0 | BT52: =IF(BS52>=60,1,0) -> 0 | BU52: =$BE$7 -> 13.75 | BV52: =BF52 -> 0 | BW52: =BV52/BU52*100 -> 0 | BX52: =IF(BW52>=60,1,0) -> 0 | BY52: =#REF! -> #REF! | BZ52: =#REF! -> #REF! | CA52: =(BZ52/BY52)*100 -> #REF! | CB52: =IF(CA52>=60,1,0) -> #REF!
A53: 46 | V53: =SUM(D53:U53) -> 0 | AW53: =SUM(X53:AV53) -> 0 | AZ53: =SUM(D53:H53) -> 0 | BB53: =SUM(I53:O53) -> 0 | BD53: =SUM(P53:S53) -> 0 | BF53: =SUM(T53:U53) -> 0 | BI53: =$AY$7 -> 38.75 | BJ53: =AZ53 -> 0 | BK53: =(BJ53/BI50)*100 -> 0 | BL53: =IF(BK53>=$BL$4,1,0) -> 0 | BM53: =$BA$7 -> 27.5 | BN53: =BB53 -> 0 | BO53: =BN53/BM53*100 -> 0 | BP53: =IF(BO53>=60,1,0) -> 0 | BQ53: =$BC$7 -> 20 | BR53: =BD53 -> 0 | BS53: =BR53/BQ53*100 -> 0 | BT53: =IF(BS53>=60,1,0) -> 0 | BU53: =$BE$7 -> 13.75 | BV53: =BF53 -> 0 | BW53: =BV53/BU53*100 -> 0 | BX53: =IF(BW53>=60,1,0) -> 0 | BY53: =#REF! -> #REF! | BZ53: =#REF! -> #REF! | CA53: =(BZ53/BY53)*100 -> #REF! | CB53: =IF(CA53>=60,1,0) -> #REF!
A54: 47 | V54: =SUM(D54:U54) -> 0 | AW54: =SUM(X54:AV54) -> 0 | AZ54: =SUM(D54:H54) -> 0 | BB54: =SUM(I54:O54) -> 0 | BD54: =SUM(P54:S54) -> 0 | BF54: =SUM(T54:U54) -> 0 | BI54: =$AY$7 -> 38.75 | BJ54: =AZ54 -> 0 | BK54: =(BJ54/BI51)*100 -> 0 | BL54: =IF(BK54>=$BL$4,1,0) -> 0 | BM54: =$BA$7 -> 27.5 | BN54: =BB54 -> 0 | BO54: =BN54/BM54*100 -> 0 | BP54: =IF(BO54>=60,1,0) -> 0 | BQ54: =$BC$7 -> 20 | BR54: =BD54 -> 0 | BS54: =BR54/BQ54*100 -> 0 | BT54: =IF(BS54>=60,1,0) -> 0 | BU54: =$BE$7 -> 13.75 | BV54: =BF54 -> 0 | BW54: =BV54/BU54*100 -> 0 | BX54: =IF(BW54>=60,1,0) -> 0 | BY54: =#REF! -> #REF! | BZ54: =#REF! -> #REF! | CA54: =(BZ54/BY54)*100 -> #REF! | CB54: =IF(CA54>=60,1,0) -> #REF!
A55: 48 | V55: =SUM(D55:U55) -> 0 | AW55: =SUM(X55:AV55) -> 0 | AZ55: =SUM(D55:H55) -> 0 | BB55: =SUM(I55:O55) -> 0 | BD55: =SUM(P55:S55) -> 0 | BF55: =SUM(T55:U55) -> 0 | BI55: =$AY$7 -> 38.75 | BJ55: =AZ55 -> 0 | BK55: =(BJ55/BI52)*100 -> 0 | BL55: =IF(BK55>=$BL$4,1,0) -> 0 | BM55: =$BA$7 -> 27.5 | BN55: =BB55 -> 0 | BO55: =BN55/BM55*100 -> 0 | BP55: =IF(BO55>=60,1,0) -> 0 | BQ55: =$BC$7 -> 20 | BR55: =BD55 -> 0 | BS55: =BR55/BQ55*100 -> 0 | BT55: =IF(BS55>=60,1,0) -> 0 | BU55: =$BE$7 -> 13.75 | BV55: =BF55 -> 0 | BW55: =BV55/BU55*100 -> 0 | BX55: =IF(BW55>=60,1,0) -> 0 | BY55: =#REF! -> #REF! | BZ55: =#REF! -> #REF! | CA55: =(BZ55/BY55)*100 -> #REF! | CB55: =IF(CA55>=60,1,0) -> #REF!
A56: 49 | V56: =SUM(D56:U56) -> 0 | AW56: =SUM(X56:AV56) -> 0 | AZ56: =SUM(D56:H56) -> 0 | BB56: =SUM(I56:O56) -> 0 | BD56: =SUM(P56:S56) -> 0 | BF56: =SUM(T56:U56) -> 0 | BI56: =$AY$7 -> 38.75 | BJ56: =AZ56 -> 0 | BK56: =(BJ56/BI53)*100 -> 0 | BL56: =IF(BK56>=$BL$4,1,0) -> 0 | BM56: =$BA$7 -> 27.5 | BN56: =BB56 -> 0 | BO56: =BN56/BM56*100 -> 0 | BP56: =IF(BO56>=60,1,0) -> 0 | BQ56: =$BC$7 -> 20 | BR56: =BD56 -> 0 | BS56: =BR56/BQ56*100 -> 0 | BT56: =IF(BS56>=60,1,0) -> 0 | BU56: =$BE$7 -> 13.75 | BV56: =BF56 -> 0 | BW56: =BV56/BU56*100 -> 0 | BX56: =IF(BW56>=60,1,0) -> 0 | BY56: =#REF! -> #REF! | BZ56: =#REF! -> #REF! | CA56: =(BZ56/BY56)*100 -> #REF! | CB56: =IF(CA56>=60,1,0) -> #REF!
...

Sheet CO-PO Attainment Endsem
C2: Course Name : | D2: ='CO-PO Direct Attainment'!D2 -> 0
C3: Course Code : | D3: ='CO-PO Direct Attainment'!D3 -> 0
C4: Semester : | D4: ='CO-PO Direct Attainment'!D4 -> 0
C5: Credits : | D5: ='CO-PO Direct Attainment'!D5 -> 0
C6: Faculty : | D6: ='CO-PO Direct Attainment'!D6 -> 0
C10: CO Attainment Grading Scale
C11: % of students achieving target | D11: SCORE
A12: Table 1 | C12: >20 and <=40 | D12: 1
C13: >40 and <=50 | D13: 2
C14: >50 | D14: 3
C15: <20 | D15: 0
B18: Course Outcome | D18: CO Attainment Score
D19: % of students attained Target | E19: Score
B20: CO1 | D20: =#REF! -> #REF! | E20: 3
B21: CO2 | D21: =#REF! -> #REF! | E21: =D21*3/70 -> #REF!
A22: Table2 | B22: CO3 | D22: =#REF! -> #REF! | E22: =60*3/70 -> 2.5714286
B23: CO4 | D23: =#REF! -> #REF! | E23: =D23*3/70 -> #REF!
B24: CO5 | D24: =#REF! -> #REF!
B26: CO-PO MAPPING in terms of codes (H,M and L)
B27: CO-PO Mapping | D27: PO1 | E27: PO2 | F27: PO3 | G27: PO4 | H27: PO5 | I27: PO6 | J27: PO7 | K27: PO8 | L27: PO9 | M27: PO10 | N27: PO11 | O27: PO12 | P27: PSO1 | Q27: PSO2 | R27: PSO3 | S27: PSO4
B28: CO1
A29: Table 3 | B29: CO2
B30: CO3
B31: CO4
B32: CO5
B33: 3- Strongly Related (H)
B34: 2- Moderately Related (M)
B35: 1- Related (L)
B36: 0- No relation (Blank Cells)
B39: CO-PO MAPPING in terms of grading scores (3,2 and 1)
B40: CO-PO Mapping | D40: PO1 | E40: PO2 | F40: PO3 | G40: PO4 | H40: PO5 | I40: PO6 | J40: PO7 | K40: PO8 | L40: PO9 | M40: PO10 | N40: PO11 | O40: PO12 | P40: PSO1 | Q40: PSO2 | R40: PSO3 | S40: PSO4
B41: CO1 | D41: 2 | E41: 2 | F41: 3 | G41: 2 | H41: 1
A42: Table 4 | B42: CO2 | D42: 3 | E42: 1 | F42: 2 | G42: 3 | H42: 1
B43: CO3 | D43: 3 | E43: 1 | F43: 2 | G43: 3 | H43: 1
B44: CO4 | D44: 3 | E44: 1 | F44: 2 | G44: 3 | H44: 1
B45: CO5
B47: PO Attainment Score
B48: CO-PO Mapping | D48: PO1 | E48: PO2 | F48: PO3 | G48: PO4 | H48: PO5 | I48: PO6 | J48: PO7 | K48: PO8 | L48: PO9 | M48: PO10 | N48: PO11 | O48: PO12 | P48: PSO1 | Q48: PSO2 | R48: PSO3 | S48: PSO4
B49: CO1 | D49: =(E20*D41)/3 -> 2 | E49: =(E20*E41) -> 6 | F49: =(E20*F41)/3 -> 3 | G49: =(E20*G41)/3 -> 2 | H49: =(E20*H41)/3 -> 1 | I49: =(E20*I41)/3 -> 0 | J49: =(E20*J41)/3 -> 0 | K49: =(E20*K41)/3 -> 0 | L49: =(E20*L41)/3 -> 0 | M49: =(E20*M41)/3 -> 0 | N49: =(E20*N41)/3 -> 0 | O49: =(E20*O41)/3 -> 0 | P49: =(E20*P41)/3 -> 0 | Q49: =(E20*Q41)/3 -> 0 | R49: =(E20*R41)/3 -> 0 | S49: =(E20*S41)/3 -> 0
B50: CO2 | D50: =(E21*D42)/3 -> #REF! | E50: =(E21*E42) -> #REF! | F50: =(E21*F42)/3 -> #REF! | G50: =(E21*G42)/3 -> #REF! | H50: =(E21*H42)/3 -> #REF! | I50: =(E21*I42)/3 -> #REF! | J50: =(E21*J42)/3 -> #REF! | K50: =(E21*K42)/3 -> #REF! | L50: =(E21*L42)/3 -> #REF! | M50: =(E21*M42)/3 -> #REF! | N50: =(E21*N42)/3 -> #REF! | O50: =(E21*O42)/3 -> #REF! | P50: =(E21*P42)/3 -> #REF! | Q50: =(E21*Q42)/3 -> #REF! | R50: =(E21*R42)/3 -> #REF! | S50: =(E21*S42)/3 -> #REF!
...

Sheet CO-PO Direct Attainment
T1: Attainment Level | U1: % of Students Achieving Target | V1: Remarks
B2: Course Name : | D2: ='Front page'!D2 -> 0 | T2: 3 | U2: 85 | V2: With a linear variation of attainment level from 3 to 2 and 2 to 1 corresponding to the variation in the % of students achieving target from 85 to 50 and 50 to 30 respectively.
B3: Course Code : | D3: ='Front page'!D3 -> 0 | T3: 2 | U3: 50
B4: Semester : | D4: ='Front page'!D9 -> 0 | T4: 1 | U4: 30
B5: Credits : | D5: ='Front page'!D10 -> 0
B6: Faculty : | D6: ='Front page'!D11 -> 0
B10: Course Outcome | D10: CO Attainment Score
D11: % of students attained Target | E11: Score
B12: CO1 | D12: ='CO Assessment'!BL223 -> 55.555556 | E12: =IF(D12="","",IF(D12>$U$2,3,IF(D12>$U$3,2+((D12-$U$3)/($U$2-$U$3)),IF(D12>$U$4,1+((D12-$U$4)/($U$3-$U$4)),0)))) -> 2.1587302
B13: CO2 | D13: ='CO Assessment'!BP223 -> 74.074074 | E13: =IF(D13="","",IF(D13>$U$2,3,IF(D13>$U$3,2+((D13-$U$3)/($U$2-$U$3)),IF(D13>$U$4,1+((D13-$U$4)/($U$3-$U$4)),0)))) -> 2.6878307
A14: Table2 | B14: CO3 | D14: ='CO Assessment'!BT223 -> 77.777778 | E14: =IF(D14="","",IF(D14>$U$2,3,IF(D14>$U$3,2+((D14-$U$3)/($U$2-$U$3)),IF(D14>$U$4,1+((D14-$U$4)/($U$3-$U$4)),0)))) -> 2.7936508
B15: CO4 | D15: ='CO Assessment'!BX223 -> 70.37037 | E15: =IF(D15="","",IF(D15>$U$2,3,IF(D15>$U$3,2+((D15-$U$3)/($U$2-$U$3)),IF(D15>$U$4,1+((D15-$U$4)/($U$3-$U$4)),0)))) -> 2.5820106
B16: CO5 | E16: =IF(D16="","",IF(D16>$U$2,3,IF(D16>$U$3,2+((D16-$U$3)/($U$2-$U$3)),IF(D16>$U$4,1+((D16-$U$4)/($U$3-$U$4)),0))))
B18: CO-PO MAPPING in terms of grading scores (3,2 and 1) | I18: PO6 | J18: PO7 | K18: PO8 | L18: PO9 | M18: PO10 | N18: PO11 | O18: PO12 | P18: PSO1 | Q18: PSO2 | R18: PSO3 | S18: PSO4
B19: CO-PO Mapping | C19: PO1 | D19: PO2 | E19: PO3 | F19: PO4 | G19: PO5
A20: Table 4 | B20: CO1 | C20: ='Front page'!H14 -> 3 | D20: ='Front page'!I14 -> 2 | E20: ='Front page'!J14 -> 3 | F20: ='Front page'!K14 -> 2 | G20: ='Front page'!L14 -> 0
B21: CO2 | C21: ='Front page'!H15 -> 3 | D21: ='Front page'!I15 -> 3 | E21: ='Front page'!J15 -> 3 | F21: ='Front page'!K15 -> 2 | G21: ='Front page'!L15 -> 0
B22: CO3 | C22: ='Front page'!H16 -> 3 | D22: ='Front page'!I16 -> 1 | E22: ='Front page'!J16 -> 3 | F22: ='Front page'!K16 -> 2 | G22: ='Front page'!L16 -> 1
B23: CO4 | C23: ='Front page'!H17 -> 3 | D23: ='Front page'!I17 -> 3 | E23: ='Front page'!J17 -> 3 | F23: ='Front page'!K17 -> 2 | G23: ='Front page'!L17 -> 1
B24: CO5 | C24: ='Front page'!H18 -> 0 | D24: ='Front page'!I18 -> 0 | E24: ='Front page'!J18 -> 0 | F24: ='Front page'!K18 -> 0 | G24: ='Front page'!L18 -> 0
B26: Direct PO Attainment Score
C27: PO1 | D27: PO2 | E27: PO3 | F27: PO4 | G27: PO5 | H27: PO6 | I27: PO7 | J27: PO8 | K27: PO9 | L27: PO10 | M27: PO11 | N27: PO12 | O27: PSO1 | P27: PSO2 | Q27: PSO3 | R27: PSO4
B28: CO1 | D28: =(#REF!*D19)/3 -> #REF! | E28: =(#REF!*E19)/3 -> #REF! | F28: =(#REF!*F19)/3 -> #REF! | G28: =(#REF!*G19)/3 -> #REF! | H28: =(#REF!*H19)/3 -> #REF! | I28: =(#REF!*I19)/3 -> #REF! | J28: =(#REF!*J19)/3 -> #REF! | K28: =(#REF!*K19)/3 -> #REF! | ... S28: =(#REF!*S19)/3 -> #REF!
B29: CO2 | D29: =(#REF!*D20)/3 -> #REF! | E29: =(#REF!*E20)/3 -> #REF! | F29: =(#REF!*F20)/3 -> #REF! | G29: =(#REF!*G20)/3 -> #REF! | H29: =(#REF!*H20)/3 -> #REF! | I29: =(#REF!*I20)/3 -> #REF! | J29: =(#REF!*J20)/3 -> #REF! | K29: =(#REF!*K20)/3 -> #REF! | ... S29: =(#REF!*S20)/3 -> #REF!
B30: CO3 | D30: =(#REF!*D21)/3 -> #REF! | E30: =(#REF!*E21)/3 -> #REF! | F30: =(#REF!*F21)/3 -> #REF! | G30: =(#REF!*G21)/3 -> #REF! | H30: =(#REF!*H21)/3 -> #REF! | I30: =(#REF!*I21)/3 -> #REF! | J30: =(#REF!*J21)/3 -> #REF! | K30: =(#REF!*K21)/3 -> #REF! | ... S30: =(#REF!*S21)/3 -> #REF!
B31: CO4 | D31: =(#REF!*D22)/3 -> #REF! | E31: =(#REF!*E22)/3 -> #REF! | F31: =(#REF!*F22)/3 -> #REF! | G31: =(#REF!*G22)/3 -> #REF! | H31: =(#REF!*H22)/3 -> #REF! | I31: =(#REF!*I22)/3 -> #REF! | J31: =(#REF!*J22)/3 -> #REF! | K31: =(#REF!*K22)/3 -> #REF! | ... S31: =(#REF!*S22)/3 -> #REF!
B32: CO5 | D32: =(#REF!*D23)/3 -> #REF! | E32: =(#REF!*E23)/3 -> #REF! | F32: =(#REF!*F23)/3 -> #REF! | G32: =(#REF!*G23)/3 -> #REF! | H32: =(#REF!*H23)/3 -> #REF! | I32: =(#REF!*I23)/3 -> #REF! | J32: =(#REF!*J23)/3 -> #REF! | K32: =(#REF!*K23)/3 -> #REF! | ... S32: =(#REF!*S23)/3 -> #REF!
B33: PO Attainment Score | C33: =((C20*IF(E12="",0,E12))+(C21*IF(E13="",0,E13))+(C22*IF(E14="",0,E14))+(C23*IF(E15="",0,E15))+(C24*IF(E16="",0,E16)))/C35 -> 2.5555556 | D33: =((D20*IF(E12="",0,E12))+(D21*IF(E13="",0,E13))+(D22*IF(E14="",0,E14))+(D23*IF(E15="",0,E15))+(D24*IF(E16="",0,E16)))/D35 -> 2.5467372 | E33: =((E20*IF(E12="",0,E12))+(E21*IF(E13="",0,E13))+(E22*IF(E14="",0,E14))+(E23*IF(E15="",0,E15))+(E24*IF(E16="",0,E16)))/E35 -> 2.5555556 | F33: =((F20*IF(E12="",0,E12))+(F21*IF(E13="",0,E13))+(F22*IF(E14="",0,E14))+(F23*IF(E15="",0,E15))+(F24*IF(E16="",0,E16)))/F35 -> 2.5555556 | G33: =((G20*IF(E12="",0,E12))+(G21*IF(E13="",0,E13))+(G22*IF(E14="",0,E14))+(G23*IF(E15="",0,E15))+(G24*IF(E16="",0,E16)))/G35 -> 2.6878307 | H33: =((I19*#REF!)+(I20*#REF!)+(I21*#REF!)+(I22*#REF!)+(I23*#REF!))/I36 -> #REF! | I33: =((J19*#REF!)+(J20*#REF!)+(J21*#REF!)+(J22*#REF!)+(J23*#REF!))/J36 -> #REF! | J33: =((K19*#REF!)+(K20*#REF!)+(K21*#REF!)+(K22*#REF!)+(K23*#REF!))/K36 -> #REF! | K33: =((L19*#REF!)+(L20*#REF!)+(L21*#REF!)+(L22*#REF!)+(L23*#REF!))/L36 -> #REF! | L33: =((M19*#REF!)+(M20*#REF!)+(M21*#REF!)+(M22*#REF!)+(M23*#REF!))/M36 -> #REF! | M33: =((N19*#REF!)+(N20*#REF!)+(N21*#REF!)+(N22*#REF!)+(N23*#REF!))/N36 -> #REF! | N33: =((O19*#REF!)+(O20*#REF!)+(O21*#REF!)+(O22*#REF!)+(O23*#REF!))/O36 -> #REF! | O33: =((P19*#REF!)+(P20*#REF!)+(P21*#REF!)+(P22*#REF!)+(P23*#REF!))/P36 -> #REF! | ... R33: =((S19*#REF!)+(S20*#REF!)+(S21*#REF!)+(S22*#REF!)+(S23*#REF!))/S36 -> #REF!
C35: =SUM(IF($E$12<>"",C20,0),IF($E$13<>"",C21,0),IF($E$14<>"",C22,0),IF($E$15<>"",C23,0),IF($E$16<>"",C24,0)) -> 12 | D35: =SUM(IF($E$12<>"",D20,0),IF($E$13<>"",D21,0),IF($E$14<>"",D22,0),IF($E$15<>"",D23,0),IF($E$16<>"",D24,0)) -> 9 | E35: =SUM(IF($E$12<>"",E20,0),IF($E$13<>"",E21,0),IF($E$14<>"",E22,0),IF($E$15<>"",E23,0),IF($E$16<>"",E24,0)) -> 12 | F35: =SUM(IF($E$12<>"",F20,0),IF($E$13<>"",F21,0),IF($E$14<>"",F22,0),IF($E$15<>"",F23,0),IF($E$16<>"",F24,0)) -> 8 | G35: =SUM(IF($E$12<>"",G20,0),IF($E$13<>"",G21,0),IF($E$14<>"",G22,0),IF($E$15<>"",G23,0),IF($E$16<>"",G24,0)) -> 2
I36: =SUM(IF(#REF!>0,I19,0),IF(#REF!>0,I20,0),IF(#REF!>0,I21,0),IF(#REF!>0,I22,0),IF(#REF!>0,I23,0)) -> #REF! | J36: =SUM(IF(#REF!>0,J19,0),IF(#REF!>0,J20,0),IF(#REF!>0,J21,0),IF(#REF!>0,J22,0),IF(#REF!>0,J23,0)) -> #REF! | K36: =SUM(IF(#REF!>0,K19,0),IF(#REF!>0,K20,0),IF(#REF!>0,K21,0),IF(#REF!>0,K22,0),IF(#REF!>0,K23,0)) -> #REF! | L36: =SUM(IF(#REF!>0,L19,0),IF(#REF!>0,L20,0),IF(#REF!>0,L21,0),IF(#REF!>0,L22,0),IF(#REF!>0,L23,0)) -> #REF! | M36: =SUM(IF(#REF!>0,M19,0),IF(#REF!>0,M20,0),IF(#REF!>0,M21,0),IF(#REF!>0,M22,0),IF(#REF!>0,M23,0)) -> #REF! | N36: =SUM(IF(#REF!>0,N19,0),IF(#REF!>0,N20,0),IF(#REF!>0,N21,0),IF(#REF!>0,N22,0),IF(#REF!>0,N23,0)) -> #REF! | O36: =SUM(IF(#REF!>0,O19,0),IF(#REF!>0,O20,0),IF(#REF!>0,O21,0),IF(#REF!>0,O22,0),IF(#REF!>0,O23,0)) -> #REF! | P36: =SUM(IF(#REF!>0,P19,0),IF(#REF!>0,P20,0),IF(#REF!>0,P21,0),IF(#REF!>0,P22,0),IF(#REF!>0,P23,0)) -> #REF! | ... S36: =SUM(IF(#REF!>0,S19,0),IF(#REF!>0,S20,0),IF(#REF!>0,S21,0),IF(#REF!>0,S22,0),IF(#REF!>0,S23,0)) -> #REF!
B38: CO-PO Mapping | C38: PO1 | D38: PO2 | E38: PO3 | F38: PO4 | G38: PO5
B39: CO1 | C39: =C20*$E12/C$35 -> 0.53968254 | D39: =D20*$E12/D$35 -> 0.47971781 | E39: =E20*$E12/E$35 -> 0.53968254 | F39: =F20*$E12/F$35 -> 0.53968254 | G39: =G20*$E12/G$35 -> 0
B40: CO2 | C40: =C21*$E13/C$35 -> 0.67195767 | D40: =D21*$E13/D$35 -> 0.89594356 | E40: =E21*$E13/E$35 -> 0.67195767 | F40: =F21*$E13/F$35 -> 0.67195767 | G40: =G21*$E13/G$35 -> 0
B41: CO3 | C41: =C22*$E14/C$35 -> 0.6984127 | D41: =D22*$E14/D$35 -> 0.31040564 | E41: =E22*$E14/E$35 -> 0.6984127 | F41: =F22*$E14/F$35 -> 0.6984127 | G41: =G22*$E14/G$35 -> 1.3968254
B42: CO4 | C42: =C23*$E15/C$35 -> 0.64550265 | D42: =D23*$E15/D$35 -> 0.86067019 | E42: =E23*$E15/E$35 -> 0.64550265 | F42: =F23*$E15/F$35 -> 0.64550265 | G42: =G23*$E15/G$35 -> 1.2910053
B43: Total | C43: =SUM(C39:C42) -> 2.5555556 | D43: =SUM(D39:D42) -> 2.5467372 | E43: =SUM(E39:E42) -> 2.5555556 | F43: =SUM(F39:F42) -> 2.5555556 | G43: =SUM(G39:G42) -> 2.6878307

Sheet Direct Attainment
B2: Course Name : | C2: ='CO-PO Indirect Attainment'!D2 -> 0
B3: Course Code : | C3: ='CO-PO Indirect Attainment'!D3 -> 0
B4: Semester : | C4: ='CO-PO Indirect Attainment'!D4 -> 0
B5: Credits : | C5: ='CO-PO Indirect Attainment'!D5 -> 0
B6: Faculty : | C6: ='CO-PO Indirect Attainment'!D6 -> 0
B8: Interim
B9: Course Code | C9: Course Name | D9: PO1 | E9: PO2 | F9: PO3 | G9: PO4 | H9: PO5 | I9: PO6 | J9: PO7 | K9: PO8 | L9: PO9 | M9: PO10 | N9: PO11 | O9: PO12 | P9: PSO1 | Q9: PSO2 | R9: PSO3 | S9: PSO4
B10: =$C$3 -> 0 | C10: =$C$2 -> 0 | D10: ='CO-PO Direct Attainment'!#REF! -> #REF! | E10: ='CO-PO Direct Attainment'!#REF! -> #REF! | F10: ='CO-PO Direct Attainment'!#REF! -> #REF! | G10: ='CO-PO Direct Attainment'!#REF! -> #REF! | H10: ='CO-PO Direct Attainment'!#REF! -> #REF! | I10: ='CO-PO Direct Attainment'!#REF! -> #REF! | J10: ='CO-PO Direct Attainment'!#REF! -> #REF! | K10: ='CO-PO Direct Attainment'!#REF! -> #REF! | ... S10: ='CO-PO Direct Attainment'!#REF! -> #REF!
B13: Endsem
B15: Course Code | C15: Course Name | D15: PO1 | E15: PO2 | F15: PO3 | G15: PO4 | H15: PO5 | I15: PO6 | J15: PO7 | K15: PO8 | L15: PO9 | M15: PO10 | N15: PO11 | O15: PO12 | P15: PSO1 | Q15: PSO2 | R15: PSO3 | S15: PSO4
B16: =$C$3 -> 0 | C16: =$C$2 -> 0 | D16: ='CO-PO Attainment Endsem'!D61 -> #REF! | E16: ='CO-PO Attainment Endsem'!E61 -> #REF! | F16: ='CO-PO Attainment Endsem'!F61 -> #REF! | G16: ='CO-PO Attainment Endsem'!G61 -> #REF! | H16: ='CO-PO Attainment Endsem'!H61 -> #REF! | I16: ='CO-PO Attainment Endsem'!I61 -> #REF! | J16: ='CO-PO Attainment Endsem'!J61 -> #REF! | K16: ='CO-PO Attainment Endsem'!K61 -> #REF! | ... S16: ='CO-PO Attainment Endsem'!S61 -> #REF!
B21: Direct PO Attainment
B22: Course Code | C22: Course Name | D22: PO1 | E22: PO2 | F22: PO3 | G22: PO4 | H22: PO5 | I22: PO6 | J22: PO7 | K22: PO8 | L22: PO9 | M22: PO10 | N22: PO11 | O22: PO12 | P22: PSO1 | Q22: PSO2 | R22: PSO3 | S22: PSO4
B23: =$C$3 -> 0 | C23: =$C$2 -> 0 | D23: =((0.6*D10)+(0.4*D16)) -> #REF! | E23: =((0.6*E10)+(0.4*E16)) -> #REF! | F23: =((0.6*F10)+(0.4*F16)) -> #REF! | G23: =((0.6*G10)+(0.4*G16)) -> #REF! | H23: =0.85*((0.6*H10)+(0.4*H16)) -> #REF! | I23: =0.85*((0.6*I10)+(0.4*I16)) -> #REF! | J23: =0.85*((0.6*J10)+(0.4*J16)) -> #REF! | K23: =0.85*((0.6*K10)+(0.4*K16)) -> #REF! | L23: =0.85*((0.6*L10)+(0.4*L16)) -> #REF! | M23: =0.85*((0.6*M10)+(0.4*M16)) -> #REF! | N23: =0.85*((0.6*N10)+(0.4*N16)) -> #REF! | O23: =0.85*((0.6*O10)+(0.4*O16)) -> #REF! | ... S23: =0.85*((0.6*S10)+(0.4*S16)) -> #REF!

Sheet CO-PO Indirect Attainment
B2: Course Name : | D2: ='Front page'!D2 -> 0
B3: Course Code : | D3: ='Front page'!D3 -> 0
B4: Semester : | D4: ='Front page'!D9 -> 0
B5: Credits : | D5: ='Front page'!D10 -> 0
B6: Faculty : | D6: ='Front page'!D11 -> 0
D11: PROPORTION OF STUDENTS
D12: VH | E12: H | F12: M | G12: L | H12: VL | I12: Total | K12: CO Grading Index (Course Survey) | L12: Score
B13: Grading Index | D13: 5 | E13: 4 | F13: 3 | G13: 2 | H13: 1
B14: CO1 | D14: 9 | E14: 10 | F14: 6 | I14: =SUM(D14:H14) -> 25 | K14: =(SUMPRODUCT(D14:H14,D13:H13))/I14 -> 4.12 | L14: =3*K14/5 -> 2.472
A15: Table 1 | B15: CO2 | D15: 7 | E15: 13 | F15: 4 | G15: 1 | I15: =SUM(D15:H15) -> 25 | K15: =(SUMPRODUCT(D15:H15,D13:H13))/I15 -> 4.04 | L15: =3*K15/5 -> 2.424
B16: CO3 | D16: 11 | E16: 8 | F16: 6 | I16: =SUM(D16:H16) -> 25 | K16: =SUMPRODUCT((D16:H16)/I16,$D$13:$H$13) -> 4.2 | L16: =3*K16/5 -> 2.52
B17: CO4 | D17: 10 | E17: 10 | F17: 5 | I17: =SUM(D17:H17) -> 25 | K17: =SUMPRODUCT((D17:H17)/I17,$D$13:$H$13) -> 4.2 | L17: =3*K17/5 -> 2.52
B18: CO5 | I18: =SUM(D18:H18) -> 0
B21: CO-PO MAPPING in terms of grading scores (3,2 and 1)
B22: CO-PO Mapping | D22: PO1 | E22: PO2 | F22: PO3 | G22: PO4 | H22: PO5
B23: CO1 | D23: 3 | E23: 2 | F23: 3 | G23: 2 | H23: 0
A24: Table 4 | B24: CO2 | D24: 3 | E24: 3 | F24: 3 | G24: 2 | H24: 0
B25: CO3 | D25: 3 | E25: 1 | F25: 3 | G25: 2 | H25: 1
B26: CO4 | D26: 3 | E26: 3 | F26: 3 | G26: 2 | H26: 1
B27: CO5
A31: Course Exit Survey PO attainment
A32: Semester | B32: Course Code | C32: Course Name | D32: PO1 | E32: PO2 | F32: PO3 | G32: PO4 | H32: PO5
A33: =$D$4 -> 0 | B33: =$D$3 -> 0 | C33: =$D$2 -> 0 | D33: =((D23*L14)+(D24*L15)+(D25*L16)+(D26*L17)+(D27*L18))/(SUM(D23:D27)) -> 2.484 | E33: =((E23*L14)+(E24*L15)+(E25*L16)+(E26*L17)+(E27*L18))/(SUM(E23:E27)) -> 2.4773333 | F33: =((F23*L14)+(F24*L15)+(F25*L16)+(F26*L17)+(F27*L18))/(SUM(F23:F27)) -> 2.484 | G33: =((G23*L14)+(G24*L15)+(G25*L16)+(G26*L17)+(G27*L18))/(SUM(G23:G27)) -> 2.484 | H33: =((H23*L14)+(H24*L15)+(H25*L16)+(H26*L17)+(H27*L18))/(SUM(H23:H27)) -> 2.52

Sheet FInal Attainment
B2: Course Name : | C2: ='CO-PO Indirect Attainment'!D2 -> 0
B3: Course Code : | C3: ='CO-PO Indirect Attainment'!D3 -> 0
B4: Semester : | C4: ='CO-PO Indirect Attainment'!D4 -> 0
B5: Credits : | C5: ='CO-PO Indirect Attainment'!D5 -> 0
B6: Faculty : | C6: ='CO-PO Indirect Attainment'!D6 -> 0
B8: Interim
B9: Course Code | C9: Course Name | D9: PO1 | E9: PO2 | F9: PO3 | G9: PO4 | H9: PO5 | I9: PO6 | J9: PO7 | K9: PO8 | L9: PO9 | M9: PO10 | N9: PO11 | O9: PO12 | P9: PSO1 | Q9: PSO2 | R9: PSO3 | S9: PSO4
B10: =$C$3 -> 0 | C10: =$C$2 -> 0 | D10: ='CO-PO Direct Attainment'!#REF! -> #REF! | E10: ='CO-PO Direct Attainment'!#REF! -> #REF! | F10: ='CO-PO Direct Attainment'!#REF! -> #REF! | G10: ='CO-PO Direct Attainment'!#REF! -> #REF! | H10: ='CO-PO Direct Attainment'!#REF! -> #REF! | I10: ='CO-PO Direct Attainment'!#REF! -> #REF! | J10: ='CO-PO Direct Attainment'!#REF! -> #REF! | K10: ='CO-PO Direct Attainment'!#REF! -> #REF! | ... S10: ='CO-PO Direct Attainment'!#REF! -> #REF!
B13: Endsem
B15: Course Code | C15: Course Name | D15: PO1 | E15: PO2 | F15: PO3 | G15: PO4 | H15: PO5 | I15: PO6 | J15: PO7 | K15: PO8 | L15: PO9 | M15: PO10 | N15: PO11 | O15: PO12 | P15: PSO1 | Q15: PSO2 | R15: PSO3 | S15: PSO4
B16: =$C$3 -> 0 | C16: =$C$2 -> 0 | D16: ='CO-PO Attainment Endsem'!D61 -> #REF! | E16: ='CO-PO Attainment Endsem'!E61 -> #REF! | F16: ='CO-PO Attainment Endsem'!F61 -> #REF! | G16: ='CO-PO Attainment Endsem'!G61 -> #REF! | H16: ='CO-PO Attainment Endsem'!H61 -> #REF! | I16: ='CO-PO Attainment Endsem'!I61 -> #REF! | J16: ='CO-PO Attainment Endsem'!J61 -> #REF! | K16: ='CO-PO Attainment Endsem'!K61 -> #REF! | ... S16: ='CO-PO Attainment Endsem'!S61 -> #REF!
B19: Exit Survey
B20: Course Code | C20: Course Name | D20: PO1 | E20: PO2 | F20: PO3 | G20: PO4 | H20: PO5 | I20: PO6 | J20: PO7 | K20: PO8 | L20: PO9 | M20: PO10 | N20: PO11 | O20: PO12 | P20: PSO1 | Q20: PSO2 | R20: PSO3 | S20: PSO4
B21: =$C$3 -> 0 | C21: =$C$2 -> 0 | D21: ='CO-PO Indirect Attainment'!D33 -> 2.484 | E21: ='CO-PO Indirect Attainment'!E33 -> 2.4773333 | F21: ='CO-PO Indirect Attainment'!F33 -> 2.484 | G21: ='CO-PO Indirect Attainment'!G33 -> 2.484 | H21: ='CO-PO Indirect Attainment'!H33 -> 2.52 | I21: ='CO-PO Indirect Attainment'!#REF! -> #REF! | J21: ='CO-PO Indirect Attainment'!#REF! -> #REF! | K21: ='CO-PO Indirect Attainment'!#REF! -> #REF! | L21: ='CO-PO Indirect Attainment'!#REF! -> #REF! | M21: ='CO-PO Indirect Attainment'!#REF! -> #REF! | N21: ='CO-PO Indirect Attainment'!#REF! -> #REF! | O21: ='CO-PO Indirect Attainment'!#REF! -> #REF! | P21: ='CO-PO Indirect Attainment'!#REF! -> #REF! | ... S21: ='CO-PO Indirect Attainment'!#REF! -> #REF!
B24: Final PO Attainment
B25: Course Code | C25: Course Name | D25: PO1 | E25: PO2 | F25: PO3 | G25: PO4 | H25: PO5 | I25: PO6 | J25: PO7 | K25: PO8 | L25: PO9 | M25: PO10 | N25: PO11 | O25: PO12 | P25: PSO1 | Q25: PSO2 | R25: PSO3 | S25: PSO4
B26: =$C$3 -> 0 | C26: =$C$2 -> 0 | D26: =(0.4*D10)+(0.4*D16)+(0.2*D21) -> #REF! | E26: =(0.4*E10)+(0.4*E16)+(0.2*E21) -> #REF! | F26: =(0.4*F10)+(0.4*F16)+(0.2*F21) -> #REF! | G26: =(0.4*G10)+(0.4*G16)+(0.2*G21) -> #REF! | H26: =(0.4*H10)+(0.4*H16)+(0.2*H21) -> #REF! | I26: =(0.4*I10)+(0.4*I16)+(0.2*I21) -> #REF! | J26: =(0.4*J10)+(0.4*J16)+(0.2*J21) -> #REF! | K26: =(0.4*K10)+(0.4*K16)+(0.2*K21) -> #REF! | ... S26: =(0.4*S10)+(0.4*S16)+(0.2*S21) -> #REF!
